Workbook

Sheet Inventory
B1: No. 序号 | C1: K | D1: Pic. 图片 | E1: Chinese Name 中文名称 | F1: English Name 英文名称 | G1: Brand(supplier) 品牌 | H1: Model 型号 | I1: Safetystock 安全库存 | J1: Units 单位 | K1: Group 类别 | L1: 等级 class | M1: 单价 unit CNY | N1: Location 库存位置 | O1: Original quantity 原始库存 | P1: Quantity 库存数量 | Q1: material NO. 物料号 | R1: 总价 tatal CNY | S1: reorder quantity 再订货量 | T1: 交货期 deliver period | U1: Supplier channel 供货渠道 | V1: 产线 line | W1: 有效期至 period of validity | X1: 货期 Lead Time | Y1: 备注 | Z1: 唯一性 unique | AA1: 质量 Q | AB1: 安全 S | AC1: 价格 V | AD1: 交期 D | AE1: 所在设备重要性 P | AF1: 分值 Sum
B2: 2931 | E2: 压花玻纤过滤器 | F2: glass fibre filter | G2: JAF | H2: 592*592*96 flange | I2: 12 | J2: Ea | K2: M | L2: A | N2: MT10-A1 | O2: 25 | P2: =O2+SUMIF(IN!F:F,Inventory!H:H,IN!M:M)-SUMIF(OUT!F:F,Inventory!H:H,OUT!M:M) -> 23 | Q2: T.03.03.M0532 | R2: =M2*P2 -> 0 | T2: 30 | U2: C | V2: EM | W2: 1825 | X2: 15 | Z2: 0 | AA2: 5 | AB2: 3 | AC2: 4 | AD2: 5 | AE2: 5 | AF2: =AA2*0.1+AB2*0.1+AC2*0.2+AD2*0.3+AE2*0.3 -> 4.6
B3: 3829 | E3: 压花玻纤过滤器 | F3: glass fibre filter | G3: JAF 595*287 | H3: 592*287*96mm flange | I3: 2 | J3: Ea | K3: M | L3: A | N3: MT10-A1 | O3: 2 | P3: =O3+SUMIF(IN!F:F,Inventory!H:H,IN!M:M)-SUMIF(OUT!F:F,Inventory!H:H,OUT!M:M) -> 0 | R3: =M3*P3 -> 0 | T3: 30 | U3: L | V3: EM5 | W3: 3650 | X3: 30 | Z3: 0 | AA3: 5 | AB3: 3 | AC3: 4 | AD3: 5 | AE3: 5 | AF3: =AA3*0.1+AB3*0.1+AC3*0.2+AD3*0.3+AE3*0.3 -> 4.6
B4: 0637 | E4: 气缸 | F4: steam cylinder | G4: FESTO 578005 | H4: DSBC-X-L-63-1000-PPVA-M16P | I4: 1 | J4: Ea | K4: M | L4: C | N4: MT10-A1 | O4: 1 | P4: =O4+SUMIF(IN!F:F,Inventory!H:H,IN!M:M)-SUMIF(OUT!F:F,Inventory!H:H,OUT!M:M) -> 1 | Q4: T.03.03.M0074 | R4: =M4*P4 -> 0 | T4: 30 | U4: C | V4: CM | W4: 1000 | X4: 60 | Z4: 0 | AA4: 5 | AB4: 4 | AC4: 5 | AD4: 5 | AE4: 5 | AF4: =AA4*0.1+AB4*0.1+AC4*0.2+AD4*0.3+AE4*0.3 -> 4.9
B5: 1172 | C5: K | E5: 压花过滤器 | F5: filter | G5: 科德宝 | H5: MCT85-0592*0592*096-IG-G-0-0-A | I5: 2 | J5: Ea | K5: M | L5: A | N5: MT10-A1 | O5: 3 | P5: 3 | Q5: T.03.03.M0321 | R5: =M5*P5 -> 0 | T5: 35 | U5: C | V5: EM | W5: 1000 | Z5: 0 | AA5: 5 | AB5: 5 | AC5: 5 | AD5: 5 | AE5: 4 | AF5: =AA5*0.1+AB5*0.1+AC5*0.2+AD5*0.3+AE5*0.3 -> 4.7
B6: 1818 | E6: 印刷扁过滤器 | F6: filter | G6: FOT | H6: MCT85-0592*0878*050-DG-A-5-3 | I6: 2 | J6: Ea | K6: M | L6: B | N6: MT10-A1 | O6: 5 | P6: =O6+SUMIF(IN!F:F,Inventory!H:H,IN!M:M)-SUMIF(OUT!F:F,Inventory!H:H,OUT!M:M) -> 5 | Q6: T.03.03.M0560 | R6: =M6*P6 -> 0 | T6: 45 | U6: C | V6: LM | W6: 1825 | Z6: 0 | AA6: 5 | AB6: 5 | AC6: 5 | AD6: 5 | AE6: 5 | AF6: =AA6*0.1+AB6*0.1+AC6*0.2+AD6*0.3+AE6*0.3 -> 5
B7: 1819 | E7: 印刷扁过滤器 | F7: filter | G7: FOT | H7: MCT85-0290*0878*050-DG-A-5-3 | I7: 2 | J7: Ea | K7: M | L7: B | N7: MT10-A1 | O7: 5 | P7: =O7+SUMIF(IN!F:F,Inventory!H:H,IN!M:M)-SUMIF(OUT!F:F,Inventory!H:H,OUT!M:M) -> 5 | Q7: T.03.03.M0559 | R7: =M7*P7 -> 0 | T7: 45 | U7: C | V7: LM | W7: 1825 | Z7: 0 | AA7: 5 | AB7: 4 | AC7: 5 | AD7: 5 | AE7: 4 | AF7: =AA7*0.1+AB7*0.1+AC7*0.2+AD7*0.3+AE7*0.3 -> 4.6
B8: 0587 | E8: 气缸 | F8: steam cylinder | G8: FESTO 536327 | H8: ADN-50-50-I-P-A | I8: 1 | J8: Ea | K8: M | L8: B | N8: MT10-A2 | O8: 4 | P8: =O8+SUMIF(IN!F:F,Inventory!H:H,IN!M:M)-SUMIF(OUT!F:F,Inventory!H:H,OUT!M:M) -> 4 | Q8: T.03.03.M0073 | R8: =M8*P8 -> 0 | T8: 60 | U8: O | V8: PMR | W8: 1000 | X8: 30 | Z8: 0 | AA8: 5 | AB8: 5 | AC8: 5 | AD8: 5 | AE8: 5 | AF8: =AA8*0.1+AB8*0.1+AC8*0.2+AD8*0.3+AE8*0.3 -> 5
B9: 0593 | E9: 气缸 | F9: steam cylinder | G9: FESTO 578949 | H9: DSNU-25-90-PPV-A | I9: 1 | J9: Ea | K9: M | L9: B | N9: MT10-A2 | O9: 1 | P9: =O9+SUMIF(IN!F:F,Inventory!H:H,IN!M:M)-SUMIF(OUT!F:F,Inventory!H:H,OUT!M:M) -> 1 | Q9: T.03.03.M0083 | R9: =M9*P9 -> 0 | T9: 60 | U9: C | W9: 3650 | X9: 30 | Z9: 0 | AA9: 5 | AB9: 5 | AC9: 3 | AD9: 5 | AE9: 5 | AF9: =AA9*0.1+AB9*0.1+AC9*0.2+AD9*0.3+AE9*0.3 -> 4.6
B10: 0594 | E10: 气缸 | F10: steam cylinder | G10: CHELIC | H10: JD32X40-B | I10: 1 | J10: Ea | K10: M | L10: B | N10: MT10-A2 | O10: 2 | P10: =O10+SUMIF(IN!F:F,Inventory!H:H,IN!M:M)-SUMIF(OUT!F:F,Inventory!H:H,OUT!M:M) -> 2 | Q10: T.03.03.M0049 | R10: =M10*P10 -> 0 | T10: 45 | U10: C | V10: PMR | W10: 1000 | Z10: 0 | AA10: 4 | AB10: 5 | AC10: 5 | AD10: 4 | AE10: 5 | AF10: =AA10*0.1+AB10*0.1+AC10*0.2+AD10*0.3+AE10*0.3 -> 4.6
B11: 0595 | C11: K | E11: 气缸 | F11: steam cylinder | G11: IMI NORGREN | H11: RT/57240/M/EX/40 | I11: 2 | J11: Ea | K11: M | L11: B | N11: MT10-A2 | O11: 4 | P11: =O11+SUMIF(IN!F:F,Inventory!H:H,IN!M:M)-SUMIF(OUT!F:F,Inventory!H:H,OUT!M:M) -> 4 | Q11: T.03.03.M0156 T.03.03.M0552 | R11: =M11*P11 -> 0 | T11: 60 | U11: O | V11: LM | W11: 1000 | Z11: 0 | AA11: 4 | AB11: 4 | AC11: 4 | AD11: 5 | AE11: 5 | AF11: =AA11*0.1+AB11*0.1+AC11*0.2+AD11*0.3+AE11*0.3 -> 4.6
B12: 0602 | E12: 气缸 | F12: cylinder | G12: CHELIC | H12: DU100-150 | I12: 2 | J12: Ea | K12: M | L12: B | N12: MT10-A2 | O12: 5 | P12: =O12+SUMIF(IN!F:F,Inventory!H:H,IN!M:M)-SUMIF(OUT!F:F,Inventory!H:H,OUT!M:M) -> 4 | Q12: T.03.03.M0214 | R12: =M12*P12 -> 0 | T12: 30 | U12: L | V12: EM | W12: 1000 | Z12: 0 | AA12: 5 | AB12: 1 | AC12: 5 | AD12: 5 | AE12: 5 | AF12: =AA12*0.1+AB12*0.1+AC12*0.2+AD12*0.3+AE12*0.3 -> 4.6
B13: 0604 | E13: 气缸 | F13: sliding seat sylinder | G13: CHELIC | H13: JCF 6375 | I13: 1 | J13: Ea | K13: M | L13: B | N13: MT10-A2 | O13: 1 | P13: =O13+SUMIF(IN!F:F,Inventory!H:H,IN!M:M)-SUMIF(OUT!F:F,Inventory!H:H,OUT!M:M) -> 2 | Q13: T.03.03.M0223 | R13: =M13*P13 -> 0 | T13: 30 | U13: O | W13: 1000 | Z13: 0 | AA13: 2 | AB13: 5 | AC13: 5 | AD13: 5 | AE13: 5 | AF13: =AA13*0.1+AB13*0.1+AC13*0.2+AD13*0.3+AE13*0.3 -> 4.7
B14: 0620 | E14: 气缸 | F14: steam cylinder | G14: FESTO 188264 | H14: ADVC-50-10-I-P-A | I14: 1 | J14: Ea | K14: M | L14: C | N14: MT10-A2 | O14: 2 | P14: =O14+SUMIF(IN!F:F,Inventory!H:H,IN!M:M)-SUMIF(OUT!F:F,Inventory!H:H,OUT!M:M) -> 2 | R14: =M14*P14 -> 0 | T14: 30 | U14: O | V14: LM | W14: 1000 | Z14: 0 | AA14: 5 | AB14: 5 | AC14: 3 | AD14: 5 | AE14: 5 | AF14: =AA14*0.1+AB14*0.1+AC14*0.2+AD14*0.3+AE14*0.3 -> 4.6
B15: 0622 | E15: 气缸 | F15: steam cylinder | G15: FESTO 1366950 | H15: DSBC-50-50-PPVA-N3 | I15: 1 | J15: Ea | K15: M | L15: B | N15: MT10-A2 | O15: 2 | P15: =O15+SUMIF(IN!F:F,Inventory!H:H,IN!M:M)-SUMIF(OUT!F:F,Inventory!H:H,OUT!M:M) -> 2 | R15: =M15*P15 -> 0 | T15: 45 | U15: C | V15: PMR | W15: 1000 | Z15: 0 | AA15: 5 | AB15: 5 | AC15: 5 | AD15: 4 | AE15: 5 | AF15: =AA15*0.1+AB15*0.1+AC15*0.2+AD15*0.3+AE15*0.3 -> 4.7
B16: 0633 | C16: K | E16: 气缸 | F16: steam cylinder | G16: FESTO 19245 | H16: DSNU-25-40-PPV-A | I16: 2 | J16: Ea | K16: M | L16: B | N16: MT10-A2 | O16: 3 | P16: =O16+SUMIF(IN!F:F,Inventory!H:H,IN!M:M)-SUMIF(OUT!F:F,Inventory!H:H,OUT!M:M) -> 3 | Q16: T.03.03.M0082 | R16: =M16*P16 -> 0 | T16: 60 | U16: C | V16: CM | W16: 3650 | Z16: 0 | AA16: 5 | AB16: 4 | AC16: 4 | AD16: 5 | AE16: 5 | AF16: =AA16*0.1+AB16*0.1+AC16*0.2+AD16*0.3+AE16*0.3 -> 4.7
B17: 1568 | E17: 气缸 | F17: steam cylinder | G17: CHELIC | H17: DU50100CA | I17: 1 | J17: Ea | K17: M | L17: B | N17: MT10-A2 | O17: 2 | P17: =O17+SUMIF(IN!F:F,Inventory!H:H,IN!M:M)-SUMIF(OUT!F:F,Inventory!H:H,OUT!M:M) -> 2 | R17: =M17*P17 -> 0 | T17: 45 | U17: C | W17: 1000 | Z17: 0 | AA17: 5 | AB17: 1 | AC17: 5 | AD17: 5 | AE17: 5 | AF17: =AA17*0.1+AB17*0.1+AC17*0.2+AD17*0.3+AE17*0.3 -> 4.6
B18: 1571 | E18: 气缸 | F18: steam cylinder | G18: CHELIC | H18: DU8050FA | I18: 1 | J18: Ea | K18: M | L18: B | N18: MT10-A2 | O18: 3 | P18: =O18+SUMIF(IN!F:F,Inventory!H:H,IN!M:M)-SUMIF(OUT!F:F,Inventory!H:H,OUT!M:M) -> 3 | Q18: T.03.03.M0241 | R18: =M18*P18 -> 0 | T18: 45 | U18: C | W18: 1000 | Z18: 0 | AA18: 3 | AB18: 4 | AC18: 5 | AD18: 5 | AE18: 5 | AF18: =AA18*0.1+AB18*0.1+AC18*0.2+AD18*0.3+AE18*0.3 -> 4.7
B19: 1576 | C19: K | E19: 手动换向阀 | F19: hand-operated direction valve | G19: SMUK | H19: XQ341061.0 | I19: 4 | J19: Ea | K19: M | L19: B | N19: MT10-A2 | O19: 5 | P19: =O19+SUMIF(IN!F:F,Inventory!H:H,IN!M:M)-SUMIF(OUT!F:F,Inventory!H:H,OUT!M:M) -> 8 | Q19: T.03.03.M0052 | R19: =M19*P19 -> 0 | T19: 60 | U19: C | V19: SM/EM | W19: 1825 | X19: 30 | Z19: 0 | AA19: 5 | AB19: 5 | AC19: 4 | AD19: 5 | AE19: 5 | AF19: =AA19*0.1+AB19*0.1+AC19*0.2+AD19*0.3+AE19*0.3 -> 4.8
B20: 1570 | C20: K | E20: 涂布三站气动元件 | F20: Coated three station pneumatic components | G20: AIRON | H20: SAO.063.00750 | I20: 1 | J20: Ea | K20: E | L20: B | N20: MT10-A3 | O20: 1 | P20: =O20+SUMIF(IN!F:F,Inventory!H:H,IN!M:M)-SUMIF(OUT!F:F,Inventory!H:H,OUT!M:M) -> 1 | Q20: T.03.03.M0078 | R20: =M20*P20 -> 0 | T20: 30 | U20: C | W20: 1000 | X20: 30 | Z20: 0 | AA20: 5 | AB20: 5 | AC20: 5 | AD20: 4 | AE20: 5 | AF20: =AA20*0.1+AB20*0.1+AC20*0.2+AD20*0.3+AE20*0.3 -> 4.7
B21: 3308 | E21: 气缸 | F21: steam cylinder | G21: CHELIC | H21: DU50*50 | I21: 1 | J21: Ea | K21: M | L21: B | N21: MT10-A3 | O21: 2 | P21: =O21+SUMIF(IN!F:F,Inventory!H:H,IN!M:M)-SUMIF(OUT!F:F,Inventory!H:H,OUT!M:M) -> 2 | R21: =M21*P21 -> 0 | T21: 30 | U21: L | V21: EM | W21: 3650 | X21: 30 | Z21: 0 | AA21: 5 | AB21: 5 | AC21: 5 | AD21: 5 | AE21: 4 | AF21: =AA21*0.1+AB21*0.1+AC21*0.2+AD21*0.3+AE21*0.3 -> 4.7
B22: 0572 | E22: 气缸 | F22: steam cylinder | G22: FESTO 1383582 | H22: DSBC-63-100-PPVA-N3 | I22: 1 | J22: Ea | K22: M | L22: C | N22: MT10-A3 | O22: 2 | P22: =O22+SUMIF(IN!F:F,Inventory!H:H,IN!M:M)-SUMIF(OUT!F:F,Inventory!H:H,OUT!M:M) -> 2 | R22: =M22*P22 -> 0 | T22: 45 | U22: O | W22: 1000 | X22: 30 | Z22: 0 | AA22: 2 | AB22: 5 | AC22: 5 | AD22: 5 | AE22: 5 | AF22: =AA22*0.1+AB22*0.1+AC22*0.2+AD22*0.3+AE22*0.3 -> 4.7
B23: 0598 | E23: 气缸 | F23: steam cylinder | G23: FESTO 1383335 | H23: DSBC-80-50-PPVA-N3 | I23: 1 | J23: Ea | K23: M | L23: B | N23: MT10-A3 | O23: 4 | P23: =O23+SUMIF(IN!F:F,Inventory!H:H,IN!M:M)-SUMIF(OUT!F:F,Inventory!H:H,OUT!M:M) -> 4 | Q23: T.03.03.M0075 | R23: =M23*P23 -> 0 | T23: 60 | U23: C | W23: 1000 | Z23: 0 | AA23: 5 | AB23: 4 | AC23: 5 | AD23: 5 | AE23: 4 | AF23: =AA23*0.1+AB23*0.1+AC23*0.2+AD23*0.3+AE23*0.3 -> 4.6
B24: 0599 | E24: 气缸 | F24: steam cylinder | G24: CAMOZZI | H24: 61L3P050A0125 | I24: 1 | J24: Ea | K24: M | L24: B | N24: MT10-A3 | O24: 6 | P24: =O24+SUMIF(IN!F:F,Inventory!H:H,IN!M:M)-SUMIF(OUT!F:F,Inventory!H:H,OUT!M:M) -> 6 | Q24: T.03.03.M0150 | R24: =M24*P24 -> 0 | T24: 60 | U24: L | W24: 1000 | X24: 30 | Z24: 0 | AA24: 4 | AB24: 2 | AC24: 5 | AD24: 5 | AE24: 5 | AF24: =AA24*0.1+AB24*0.1+AC24*0.2+AD24*0.3+AE24*0.3 -> 4.6
B25: 0600 | E25: 气缸 | F25: steam cylinder | G25: AIRON | H25: BFM.040.0100.BCA | I25: 1 | J25: Ea | K25: M | L25: C | N25: MT10-A3 | O25: 2 | P25: =O25+SUMIF(IN!F:F,Inventory!H:H,IN!M:M)-SUMIF(OUT!F:F,Inventory!H:H,OUT!M:M) -> 2 | R25: =M25*P25 -> 0 | T25: 45 | U25: C | W25: 1000 | Z25: 0 | AA25: 1 | AB25: 5 | AC25: 5 | AD25: 5 | AE25: 5 | AF25: =AA25*0.1+AB25*0.1+AC25*0.2+AD25*0.3+AE25*0.3 -> 4.6
B26: 0623 | E26: 气缸 | F26: steam cylinder | G26: FESTO 1366952 | H26: DSBC-50-100-PPVA-N3 | I26: 1 | J26: Ea | K26: M | L26: B | N26: MT10-A3 | O26: 3 | P26: =O26+SUMIF(IN!F:F,Inventory!H:H,IN!M:M)-SUMIF(OUT!F:F,Inventory!H:H,OUT!M:M) -> 3 | Q26: T.03.03.M0081 | R26: =M26*P26 -> 0 | T26: 45 | U26: O | W26: 1000 | Z26: 0 | AA26: 1 | AB26: 5 | AC26: 5 | AD26: 5 | AE26: 5 | AF26: =AA26*0.1+AB26*0.1+AC26*0.2+AD26*0.3+AE26*0.3 -> 4.6
B27: 0632 | E27: 气缸 | F27: steam cylinder | G27: FESTO 1383338 | H27: DSBC-80-125-PPVA-N3 | I27: 1 | J27: Ea | K27: M | L27: C | N27: MT10-A3 | O27: 2 | P27: =O27+SUMIF(IN!F:F,Inventory!H:H,IN!M:M)-SUMIF(OUT!F:F,Inventory!H:H,OUT!M:M) -> 2 | R27: =M27*P27 -> 0 | T27: 45 | U27: O | W27: 1000 | Z27: 0 | AA27: 5 | AB27: 5 | AC27: 5 | AD27: 5 | AE27: 5 | AF27: =AA27*0.1+AB27*0.1+AC27*0.2+AD27*0.3+AE27*0.3 -> 5
B28: 0634 | E28: 气缸 | F28: steam cylinder 19242 | G28: FESTO 193990 | H28: DSNU-20-200-PPV-A-S11 | I28: 1 | J28: Ea | K28: M | L28: B | N28: MT10-A3 | O28: 4 | P28: =O28+SUMIF(IN!F:F,Inventory!H:H,IN!M:M)-SUMIF(OUT!F:F,Inventory!H:H,OUT!M:M) -> 2 | Q28: T.03.03.M0080 | R28: =M28*P28 -> 0 | T28: 45 | U28: O | V28: CM | W28: 1000 | X28: 30 | Z28: 0 | AA28: 5 | AB28: 4 | AC28: 5 | AD28: 5 | AE28: 4 | AF28: =AA28*0.1+AB28*0.1+AC28*0.2+AD28*0.3+AE28*0.3 -> 4.6
B29: 0636 | E29: 气缸 | F29: steam cylinder | G29: CHELIC | H29: DU 100X750 | I29: 1 | J29: Ea | K29: M | L29: C | N29: MT10-A3 | O29: 1 | P29: =O29+SUMIF(IN!F:F,Inventory!H:H,IN!M:M)-SUMIF(OUT!F:F,Inventory!H:H,OUT!M:M) -> 1 | R29: =M29*P29 -> 0 | T29: 30 | U29: C | W29: 1000 | X29: 30 | Z29: 0 | AA29: 4 | AB29: 4 | AC29: 4 | AD29: 5 | AE29: 5 | AF29: =AA29*0.1+AB29*0.1+AC29*0.2+AD29*0.3+AE29*0.3 -> 4.6
B30: 0638 | E30: 气缸 | F30: steam cylinder | G30: FESTO | H30: DSBC-125-320-PPVA-N3-355E | I30: 1 | J30: Ea | K30: M | L30: C | N30: MT10-A3 | O30: 3 | P30: =O30+SUMIF(IN!F:F,Inventory!H:H,IN!M:M)-SUMIF(OUT!F:F,Inventory!H:H,OUT!M:M) -> 3 | R30: =M30*P30 -> 0 | T30: 45 | U30: C | W30: 1000 | X30: 30 | Z30: 0 | AA30: 4 | AB30: 5 | AC30: 4 | AD30: 5 | AE30: 5 | AF30: =AA30*0.1+AB30*0.1+AC30*0.2+AD30*0.3+AE30*0.3 -> 4.7
B31: 1925 | E31: 气缸 | F31: cylinder | G31: FESTO 170829 | H31: DFM-12-50-A-GF | I31: 1 | J31: Ea | K31: E | L31: C | N31: MT10-A3 | O31: 0 | P31: =O31+SUMIF(IN!F:F,Inventory!H:H,IN!M:M)-SUMIF(OUT!F:F,Inventory!H:H,OUT!M:M) -> 0 | R31: =M31*P31 -> 0 | T31: 60 | U31: C | W31: 1000 | X31: 30 | Z31: 0 | AA31: 5 | AB31: 4 | AC31: 5 | AD31: 5 | AE31: 4 | AF31: =AA31*0.1+AB31*0.1+AC31*0.2+AD31*0.3+AE31*0.3 -> 4.6
B32: 2407 | C32: K | E32: 轴承 | F32: Bearing | G32: NTN | H32: NTN-6309ZZ | I32: 1 | J32: Ea | K32: E | L32: A | N32: MT10-A3 | O32: 2 | P32: =O32+SUMIF(IN!F:F,Inventory!H:H,IN!M:M)-SUMIF(OUT!F:F,Inventory!H:H,OUT!M:M) -> 2 | R32: =M32*P32 -> 0 | T32: 60 | U32: O | V32: LM | W32: 1000 | X32: 30 | Z32: 0 | AA32: 4 | AB32: 5 | AC32: 5 | AD32: 5 | AE32: 4 | AF32: =AA32*0.1+AB32*0.1+AC32*0.2+AD32*0.3+AE32*0.3 -> 4.6
B33: 2546 | E33: 气缸 | F33: steam cylinder | G33: FESTO 559279 | H33: DSNU-20-250-PPS | I33: 1 | J33: Ea | K33: M | L33: B | N33: MT10-A3 | O33: 4 | P33: =O33+SUMIF(IN!F:F,Inventory!H:H,IN!M:M)-SUMIF(OUT!F:F,Inventory!H:H,OUT!M:M) -> 4 | R33: =M33*P33 -> 0 | T33: 30 | U33: C | V33: PM1 | W33: 3650 | X33: 30 | Z33: 0 | AA33: 5 | AB33: 4 | AC33: 4 | AD33: 5 | AE33: 5 | AF33: =AA33*0.1+AB33*0.1+AC33*0.2+AD33*0.3+AE33*0.3 -> 4.7
B34: 3193 | E34: 气缸 | F34: steam-cylinder | G34: 德鑫成 | H34: QGB40*500 | I34: 1 | J34: Ea | K34: M | L34: C | N34: MT10-A4 | O34: 3 | P34: =O34+SUMIF(IN!F:F,Inventory!H:H,IN!M:M)-SUMIF(OUT!F:F,Inventory!H:H,OUT!M:M) -> 4 | Q34: T.03.03.M0564 | R34: =M34*P34 -> 0 | T34: 30 | U34: L | V34: EM | W34: 3650 | X34: 30 | Z34: 0 | AA34: 5 | AB34: 3 | AC34: 5 | AD34: 5 | AE34: 5 | AF34: =AA34*0.1+AB34*0.1+AC34*0.2+AD34*0.3+AE34*0.3 -> 4.8
B35: 3633 | E35: 搅拌机油缸 | F35: oil cylinder | G35: HUGEST | H35: Φ125/100-800 | I35: 1 | J35: Ea | K35: M | L35: C | N35: MT10-A4 | O35: 1 | P35: =O35+SUMIF(IN!F:F,Inventory!H:H,IN!M:M)-SUMIF(OUT!F:F,Inventory!H:H,OUT!M:M) -> 1 | R35: =M35*P35 -> 0 | T35: 60 | U35: C | V35: PMR | W35: 3650 | X35: 60 | Z35: 0 | AA35: 2 | AB35: 5 | AC35: 5 | AD35: 5 | AE35: 5 | AF35: =AA35*0.1+AB35*0.1+AC35*0.2+AD35*0.3+AE35*0.3 -> 4.7
B36: 0571 | E36: 气缸 | F36: steam cylinder | G36: CHELIC | H36: 50X100-CA | I36: 1 | J36: Ea | K36: M | L36: C | N36: MT10-A4 | O36: 2 | P36: =O36+SUMIF(IN!F:F,Inventory!H:H,IN!M:M)-SUMIF(OUT!F:F,Inventory!H:H,OUT!M:M) -> 2 | Q36: T.03.03.M0242 | R36: =M36*P36 -> 0 | T36: 60 | U36: C | W36: 1000 | X36: 30 | Z36: 0 | AA36: 5 | AB36: 4 | AC36: 5 | AD36: 5 | AE36: 5 | AF36: =AA36*0.1+AB36*0.1+AC36*0.2+AD36*0.3+AE36*0.3 -> 4.9
B37: 0607 | E37: 气缸 | F37: steam cylinder | G37: FESTO 163430 | H37: DNC-80-200-PPV-A-EX4 | I37: 1 | J37: Ea | K37: M | L37: B | N37: MT10-A4 | O37: 1 | P37: =O37+SUMIF(IN!F:F,Inventory!H:H,IN!M:M)-SUMIF(OUT!F:F,Inventory!H:H,OUT!M:M) -> 1 | Q37: T.03.03.M0014 | R37: =M37*P37 -> 0 | T37: 30 | U37: O | W37: 1000 | Z37: 0 | AA37: 5 | AB37: 5 | AC37: 5 | AD37: 4 | AE37: 5 | AF37: =AA37*0.1+AB37*0.1+AC37*0.2+AD37*0.3+AE37*0.3 -> 4.7
B38: 0608 | E38: 气缸 | F38: steam cylinder | G38: PENUMATIC | H38: 121A500075CN | I38: 2 | J38: Ea | K38: M | L38: B | N38: MT10-A4 | O38: 3 | P38: =O38+SUMIF(IN!F:F,Inventory!H:H,IN!M:M)-SUMIF(OUT!F:F,Inventory!H:H,OUT!M:M) -> 2 | Q38: T.03.03.M0158 | R38: =M38*P38 -> 0 | T38: 60 | U38: O | V38: LM | W38: 3650 | Z38: 0 | AA38: 4 | AB38: 5 | AC38: 5 | AD38: 4 | AE38: 5 | AF38: =AA38*0.1+AB38*0.1+AC38*0.2+AD38*0.3+AE38*0.3 -> 4.6
B39: 0609 | E39: 气缸 | F39: steam cylinder | G39: SNS | H39: SC 40*500 | I39: 1 | J39: Ea | K39: M | L39: B | N39: MT10-A4 | O39: 2 | P39: =O39+SUMIF(IN!F:F,Inventory!H:H,IN!M:M)-SUMIF(OUT!F:F,Inventory!H:H,OUT!M:M) -> 2 | Q39: T.03.03.M0250 | R39: =M39*P39 -> 0 | T39: 45 | U39: O | W39: 1000 | Z39: 0 | AA39: 4 | AB39: 5 | AC39: 5 | AD39: 4 | AE39: 5 | AF39: =AA39*0.1+AB39*0.1+AC39*0.2+AD39*0.3+AE39*0.3 -> 4.6
B40: 0610 | E40: 压花对边油缸 | F40: embossed slide oil cylinder | G40: RISEN | H40: MOB-63/25*300+CA | I40: 1 | J40: Ea | K40: M | L40: C | N40: MT10-A4 | O40: 2 | P40: =O40+SUMIF(IN!F:F,Inventory!H:H,IN!M:M)-SUMIF(OUT!F:F,Inventory!H:H,OUT!M:M) -> 2 | R40: =M40*P40 -> 0 | T40: 45 | U40: E | V40: EM | W40: 1000 | Z40: 0 | AA40: 2 | AB40: 4 | AC40: 5 | AD40: 5 | AE40: 5 | AF40: =AA40*0.1+AB40*0.1+AC40*0.2+AD40*0.3+AE40*0.3 -> 4.6
...

Sheet IN
B1: K | C1: Chinese Name 中文名称 | D1: English Name 英文名称 | E1: Brand(supplier) 品牌 | F1: Model 型号 | H1: unit 单位 | I1: Group 类别 | J1: 等级 class | K1: unit 单价 CNY | L1: Location 库存位置 | M1: Quantity In 入库数量 | N1: First time Ordered 是否首次采购 | O1: Date 入库时间 | P1: total 总价 CNY | Q1: Remark
C2: 特氟龙密封圈 | D2: Teflon Gasket | E2: Rhineboni | F2: Φ85*18mm | G2: 8 | H2: Ea | I2: M | J2: B | L2: MT9-B3 | N2: 1 | O2: 46026 | P2: =K7969*M7969 -> 0
C3: 吸油木 | D3: oil-absorbing wood | E3: RHINEBONI | F3: 50X20X2200(含卡夹X2PC) | G3: 34 | H3: Ea | I3: M | J3: B | L3: MT12-F2 | M3: 30 | N3: 1 | O3: 46026 | P3: =K7970*M7970 -> 0
C4: 蓄电池 | D4: WHEEL | E4: LINDE | F4: 24V2PZS230AH 无线 | G4: 2 | H4: Ea | I4: U | J4: C | L4: MT8-B6 | M4: 2 | N4: 1 | O4: 46026 | P4: =K7971*M7971 -> 0
C5: 搅拌机 | D5: mixer | E5: 耐德尔 | F5: QJB0.85/8-260/3 | G5: 1 | H5: Ea | I5: U | J5: C | L5: MT8-D5 | M5: 1 | N5: 1 | O5: 46024 | P5: =K7972*M7972 -> 0
C6: 消防挂锁 | D6: lock | E6: BADY | F6: 38mmG01 通开 | G6: 1 | H6: Ea | I6: U | J6: C | L6: MT8-B5 | M6: 40 | N6: 1 | O6: 46024 | P6: =K7973*M7973 -> 0
C7: 鱼形缆绳锁 | D7: lock | E7: BADY | F7: BD66603 | G7: 1 | H7: Ea | I7: U | J7: C | L7: MT8-B5 | M7: 40 | N7: 1 | O7: 46024 | P7: =K7974*M7974 -> 0
C8: 万用阀门锁 | D8: lock | E8: BADY | F8: F31 | G8: 1 | H8: Ea | I8: U | J8: C | L8: MT8-B5 | M8: 5 | N8: 1 | O8: 46024 | P8: =K7975*M7975 -> 0
C9: 提升泵软联结 | D9: connection | E9: GRUNDFOS | F9: 40-32+WC-3 | G9: 1 | H9: Ea | I9: U | J9: C | L9: MT8-B5 | M9: 1 | N9: 1 | O9: 46024 | P9: =K7976*M7976 -> 0
C10: 不锈钢球阀 | D10: ball valve | E10: 奇高 DN40 | F10: 304 1 1/2寸 | G10: 5 | H10: Ea | I10: M | J10: C | L10: MT8-D4 | M10: 5 | N10: 1 | O10: 46024 | P10: =K7977*M7977 -> 0
C11: 滑轨限位 | D11: block | E11: NA | F11: EM/HGXW1 | G11: 1 | H11: Ea | I11: M | J11: C | L11: MT8-D4 | M11: 30 | N11: 1 | O11: 46024 | P11: =K7978*M7978 -> 0
C12: 时控开关 | D12: switch | E12: Delixi | F12: ZTY01 | G12: 1 | H12: Ea | I12: E | J12: C | L12: MT6-D4 | M12: 1 | N12: 1 | O12: 46024 | P12: =K7979*M7979 -> 0
C13: 电磁阀 | D13: VALVE | E13: HONEYWELL | F13: VN6013APC1000T | G13: 1 | H13: Ea | I13: M | J13: C | L13: MT10-C3 | M13: 1 | N13: 1 | O13: 46024 | P13: =K7980*M7980 -> 0
C14: LED照明灯 | D14: LED lamp | E14: 净米 | F14: YQ-LJH/68W | G14: 1 | H14: Ea | I14: U | J14: C | L14: MT8-C3 | M14: 4 | N14: 1 | O14: 46024 | P14: =K7981*M7981 -> 0
... C18: 高温胶 | D18: high temperature | E18: 美斯国顿 | F18: 1280度耐火胶/灰色 300ml | G18: 4 | H18: Ea | I18: U | J18: C | L18: MT4-F4 | M18: 4 | N18: 1 | O18: 46024 | P18: =K7985*M7985 -> 0
C19: 阀门定位器 | D19: valve positioner | E19: SAMSON | F19: 3725 | G19: 1 | H19: Ea | I19: E | J19: B | L19: MT6-C2 | M19: 2 | N19: 1 | O19: 46032 | P19: =K7986*M7986 -> 0
C20: 剪纸1安全夹头 | D20: Safety chuck | E20: COATEC | F20: RH-STW-50- 40X40X110 | G20: 1 | H20: Ea | I20: M | J20: B | L20: MT11-F6 | M20: 2 | N20: 1 | O20: 46032 | P20: =K7987*M7987 -> 0
C21: 蓄电池 | D21: WHEEL | E21: LINDE | F21: 24V3PZS345Ah侧面换 | G21: 2 | H21: Ea | I21: U | J21: C | L21: MT8-B6 | M21: 1 | N21: 1 | O21: 46024 | P21: =K7988*M7988 -> 0
C22: 电接地带 | D22: WHEEL | E22: LINDE | F22: PB300471122 | G22: 2 | H22: Ea | I22: U | J22: C | L22: MT8-B6 | M22: 6 | N22: 1 | O22: 46024 | P22: =K7989*M7989 -> 0
C23: 壳体总成 '操纵 | D23: WHEEL | E23: LINDE | F23: 3095406448 | G23: 1 | H23: Ea | I23: U | J23: C | L23: MT8-B6 | M23: 1 | N23: 1 | O23: 46024 | P23: =K7990*M7990 -> 0
C24: 跷板开关 | D24: WHEEL | E24: LINDE | F24: 0039732605 | G24: 2 | H24: Ea | I24: U | J24: C | L24: MT8-B6 | M24: 1 | N24: 1 | O24: 46024 | P24: =K7991*M7991 -> 0
C25: 铰接件 'Li | D25: WHEEL | E25: LINDE | F25: 3005430310 | G25: 1 | H25: Ea | I25: U | J25: C | L25: MT8-B6 | M25: 1 | N25: 1 | O25: 46024 | P25: =K7992*M7992 -> 0
C26: 跷板开关 | D26: WHEEL | E26: LINDE | F26: 0039732605 | G26: 2 | H26: Ea | I26: U | J26: C | L26: MT8-B6 | M26: 10 | N26: 1 | O26: 46024 | P26: =K7993*M7993 -> 0
C27: 铰接件 'Li | D27: WHEEL | E27: LINDE | F27: 3005430310 | G27: 1 | H27: Ea | I27: U | J27: C | L27: MT8-B6 | M27: 5 | N27: 1 | O27: 46024 | P27: =K7994*M7994 -> 0
C28: 切割刀座修理件 | D28: cutting cutter repaired | E28: OTOKNIFE | F28: 105*10mm | G28: 5 | H28: Ea | I28: M | J28: B | L28: MT10-C2 | M28: 5 | N28: 1 | O28: 46033 | P28: =K7995*M7995 -> 0
C29: 切割切刀修理件 | D29: cutting cutter | E29: OTOKNIFE | F29: K61001 | G29: 5 | H29: Ea | I29: M | J29: B | L29: MT10-C2 | M29: 11 | N29: 1 | O29: 46033 | P29: =K7996*M7996 -> 0
C30: 电磁阀 | D30: Solenoid valve | E30: 三叶 | F30: 2W-250-25 220V | G30: 2 | H30: Ea | I30: M | J30: B | L30: MT5-E4 | M30: 4 | N30: 1 | O30: 46033 | P30: =K7997*M7997 -> 0
C31: 石英玻璃板 | D31: quartz glass | E31: 联翩 | F31: 2402*157*3.8mm | G31: 1 | H31: Ea | I31: E | J31: A | L31: MT2-A3 | M31: 1 | N31: 1 | O31: 46034 | P31: =K7998*M7998 -> 0
... C54: 蓄电池 | D54: WHEEL | E54: LINDE | F54: '24V2PZS230AH 无线 | G54: 2 | H54: Ea | I54: U | J54: C | L54: MT8-B6 | M54: 11 | N54: 1 | O54: 46042 | P54: =K8021*M8021 -> 0
C55: 蓄电池 | D55: WHEEL | E55: LINDE | F55: 24V2PZS230AH 防爆 | G55: 2 | H55: Ea | I55: U | J55: C | L55: MT8-B6 | M55: 1 | N55: 1 | O55: 46042 | P55: =K8022*M8022 -> 0 | Q55: 上传送货单
C56: 旋转接头 | D56: rotary joint | E56: MAIER | F56: DP50L51 | G56: 1 | H56: Ea | I56: M | J56: A | L56: MT10-B4 | N56: 1 | O56: 46046 | P56: =K8023*M8023 -> 0 | Q56: 上传送货单
C57: 旋转接头 | D57: rotary joint | E57: MAIER | F57: DX265L修理件 | G57: 1 | H57: Ea | I57: M | J57: A | L57: MT10-B4 | N57: 1 | O57: 46046 | P57: =K8024*M8024 -> 0 | Q57: 上传送货单
C58: 爱曾维修包 | D58: repair kit | E58: AERZEN | F58: 180685001 | G58: 1 | H58: Ea | I58: M | J58: B | L58: MT10-D3 | M58: 1 | N58: 1 | O58: 46046 | P58: =K8025*M8025 -> 0
C59: 爱曾维修包 | D59: sealing kit | E59: AERZEN | F59: 180682000 | G59: 1 | H59: Ea | I59: M | J59: B | L59: MT10-D3 | M59: 1 | N59: 1 | O59: 46046 | P59: =K8026*M8026 -> 0
C60: CM高温红胶 | D60: high temperature | E60: 上海亨越 | F60: HS-1840 310ml | G60: 4 | H60: Ea | I60: M | J60: C | L60: MT4-F4 | M60: 6 | N60: 1 | O60: 46046 | P60: =K8027*M8027 -> 0
C61: 安全开关 | D61: sensor | E61: SICK | F61: 1069560 | G61: 1 | H61: Ea | I61: E | J61: C | L61: MT5-B4 | M61: 3 | N61: 1 | O61: 46053 | P61: =K8028*M8028 -> 0
C62: 传感器线缆 | D62: sensor | E62: SICK | F62: 2096241 | G62: 1 | H62: Ea | I62: E | J62: C | L62: MT5-B4 | M62: 3 | N62: 1 | O62: 46053 | P62: =K8029*M8029 -> 0
C63: 混浆锥斗气锤 | D63: Solenoid valve | E63: Rhineboni | F63: RHYL-120型-L150 | G63: 1 | H63: Ea | I63: M | J63: C | L63: MT11-C2 | M63: 2 | N63: 1 | O63: 46046 | P63: =K8030*M8030 -> 0
C64: 继电器 | D64: relay | E64: PHOENIX CONTACT | F64: PLC-RSC-24DC/21-21 | G64: 1 | H64: Ea | I64: E | J64: C | L64: MT5-F2 | M64: 20 | N64: 1 | O64: 46048 | P64: =K8031*M8031 -> 0
C65: 黑胶密封圈 | D65: seal ring | E65: NA 2寸 | F65: 65*5 | G65: 20 | H65: Ea | I65: M | J65: C | L65: MT7-E3 | M65: 30 | N65: 1 | O65: 46050 | P65: =K8032*M8032 -> 0
...

Sheet OUT
A1: OUT | B1: K | C1: Chinese Name 中文名称 | D1: English Name 英文名称 | E1: Brand(supplier) 品牌 | F1: Model 型号 | H1: unit 单位 | I1: Group 类别 | J1: 等级 class | K1: unit 单价 CNY | L1: Location 库存位置 | M1: Quantity Out 出库数量 | N1: Date 出库时间 | P1: total 总价 CNY | Q1: 产线 line | R1: SPA OUT STOCK | S1: total 总价 CNY
C2: 钢丝管 | D2: soft pipe | E2: 国产 | F2: 内径38mm | G2: 10 | H2: Ea | I2: M | J2: C | L2: MT12-F2 | M2: 10 | N2: 46025 | Q2: Utility
C3: MBR中空纤维膜 | D3: filter | E3: 广州超禹 | F3: CYM620-1320-PVDF | G3: 1 | H3: Ea | I3: U | J3: C | L3: MT8-E1 | M3: 1 | N3: 46027 | Q3: Utility
C4: 物位变送器 | D4: Location transmitter | E4: E+H | F4: FTL31-AA4M2AAW5J+LC | G4: 1 | H4: Ea | I4: E | J4: C | L4: MT6-F2 | M4: 1 | N4: 46028 | Q4: PMR
C5: 搅拌机 | D5: mixer | E5: 耐德尔 | F5: QJB0.85/8-260/3 | G5: 1 | H5: Ea | I5: U | J5: C | L5: MT8-D5 | M5: 1 | N5: 46028 | Q5: Utility
C6: 真空压力表 | D6: vacuum manometer | E6: 糜氏 2.5级 | F6: YN60 -0.1-0.3Mpa | G6: 1 | H6: Ea | I6: M | J6: C | L6: MT8-A3 | M6: 1 | N6: 46025 | Q6: PMR
C7: 耐震压力表 | D7: vacuum manometer | E7: 糜氏 2.5级 | F7: YN60 0-10MPa | G7: 1 | H7: Ea | I7: M | J7: C | L7: MT8-A4 | M7: 1 | N7: 46025 | Q7: PMR
C8: 反光板 | D8: plate | E8: sick 265-2754 | F8: AL15BN | G8: 3 | H8: Ea | I8: E | J8: C | L8: MT5-F5 | M8: 1 | N8: 46025 | Q8: CM2
C9: 消音器 | D9: silencer | E9: FESTO 2316 | F9: U-1/4 | G9: 8 | H9: Ea | I9: M | J9: C | L9: MT7-A4 | M9: 1 | N9: 46026 | Q9: PMR
C10: 活塞环片密封 | D10: seal | E10: Z.P. ARROW | F10: 6.20.0.0001.3 | G10: 20 | H10: Ea | I10: M | J10: C | L10: MT9-B3 | M10: 1 | N10: 46026 | Q10: PMR
C11: 切割切刀修理件 | D11: cutting cutter | E11: OTOKNIFE | F11: K61001 | G11: 5 | H11: Ea | I11: M | J11: B | L11: MT10-C2 | M11: 2 | N11: 46028 | Q11: SM5
C12: 单相二脚插头(白色) | D12: plug(white) | E12: BULL公牛 | F12: GNT-10L1 10A 250V~ | G12: 10 | H12: Ea | I12: E | J12: C | L12: MT4-C3 | M12: 4 | N12: 46027 | Q12: CM2
C13: 切割刀座修理件 | D13: cutting cutter repaired | E13: OTOKNIFE | F13: 105*10mm | G13: 5 | H13: Ea | I13: M | J13: B | L13: MT10-C2 | M13: 1 | N13: 46028 | Q13: SM5
... C84: LED灯管T8 | D84: LED lamp | E84: philips 单进电 | F84: 1200mm 18W 6500K | G84: 50 | H84: Ea | I84: U | J84: C | L84: MT4-A1 | M84: 4 | N84: 46043 | Q84: EM1/2
C85: 气枪 | D85: blow gun | E85: CEJN 080250 | F85: 8025090 | G85: 2 | H85: Ea | I85: M | J85: C | L85: MT7-A5 | M85: 2 | N85: 46045 | Q85: CM
C86: 防爆叉齿包钢 | D86: cover | E86: LINDER | F86: 用于苏DE4353 | G86: 1 | H86: Ea | I86: U | J86: C | L86: MT8-B6 | M86: 1 | N86: 46046 | Q86: Utility
C87: 蓄电池 | D87: WHEEL | E87: LINDE | F87: 24V3PzBH225AH | G87: 2 | H87: Ea | I87: U | J87: C | L87: MT8-B6 | M87: 1 | N87: 46046 | Q87: Utility
C88: 蓄电池 | D88: WHEEL | E88: LINDE | F88: '24V2PZS230AH 无线 | G88: 2 | H88: Ea | I88: U | J88: C | L88: MT8-B6 | M88: 11 | N88: 46046 | Q88: Utility
C89: 蓄电池 | D89: WHEEL | E89: LINDE | F89: 24V2PZS230AH 防爆 | G89: 2 | H89: Ea | I89: U | J89: C | L89: MT8-B6 | N89: 46046 | Q89: Utility
C90: 接触器 | D90: contactor | E90: SIEMENS | F90: 3RT6027-1AN20 | G90: 5 | H90: Ea | I90: E | J90: C | L90: MT5-F3 | M90: 4 | N90: 46044 | Q90: EM5
C91: 加热灯管 | D91: strip lamp | E91: LAMBDA | F91: 85394900/Emitter 3.85kw/LM3 | G91: 10 | H91: Ea | I91: E | J91: A | L91: IM-A2 | M91: 1 | N91: 46044 | Q91: EM1
C92: 复合轴承 | D92: Grooved ball bearing | E92: Künemund Düsseldorf GmbH | F92: 6005-C4.COMP2 | G92: 50 | H92: Ea | I92: M | J92: A | L92: MT7-D2 | M92: 4 | N92: 46045 | Q92: LM2
C93: 调心辊子轴承 574845 | D93: Self-aligning roller bearing | E93: Künemund Düsseldorf GmbH | F93: 2203.C4.P.COMP2 | G93: 60 | H93: Ea | I93: M | J93: B | L93: MT7-D2 | M93: 2 | N93: 46045 | Q93: LM2
C94: 调压阀 | D94: air vent valve | E94: SMC | F94: IR2020-F02 | G94: 1 | H94: Ea | I94: M | J94: C | L94: MT7-A4 | M94: 1 | N94: 46045 | Q94: RO
C95: LED灯管T8 | D95: LED lamp | E95: philips 单进电 | F95: 1200mm 18W 6500K | G95: 50 | H95: Ea | I95: U | J95: C | L95: MT4-A1 | M95: 7 | N95: 46045 | Q95: EM2
C96: 中间继电器 | D96: relay | E96: Schneider | F96: RXM2LB2B7 24VAC | G96: 1 | H96: Ea | I96: E | J96: C | L96: MT11-D5 | M96: 10 | N96: 46045 | Q96: CRANE/CM
C97: 水枪组件 | D97: water gun | E97: KARCHER | F97: max.4350PSK 311 F | G97: 1 | H97: Ea | I97: M | J97: C | L97: MT11-E1 | M97: 1 | N97: 46045 | Q97: RO
C98: 牙箱 | D98: tooth box | E98: 东力 | F98: 5GU-3K | G98: 2 | H98: Ea | I98: M | J98: C | L98: MT10-C5 | M98: 1 | N98: 46045 | Q98: SM1
C99: 电机 | D99: motor | E99: 东力 | F99: 5RK120GU-S3 | G99: 2 | H99: Ea | I99: E | J99: B | L99: MT10-C5 | M99: 1 | N99: 46045 | Q99: SM1
C100: 蓝色润滑脂 | D100: blue grease | E100: Mobil | F100: Mobil XHP 222 | G100: 5 | H100: Ea | I100: M | J100: B | L100: MT4-F5 | M100: 1 | N100: 46047 | Q100: CRANE/EM4
C101: 微型接触器 | D101: contactor | E101: ABB | F101: B7-30-10-F-01 | G101: 1 | H101: Ea | I101: E | J101: C | L101: MT11-D5 | M101: 2 | N101: 46047 | Q101: CRANE/LM1
... C121: 滤芯 | D121: exhaust air filter | E121: BUSCH | F121: V532140157 | G121: 12 | H121: Ea | I121: M | J121: C | L121: MT9-E3 | M121: 2 | N121: 46048 | Q121: PMR
C122: 真空泵油滤 | D122: vacuum pump oil filter | E122: BUSCH | F122: 531000002 | G122: 2 | H122: Ea | I122: M | J122: C | L122: MT9-E3 | M122: 1 | N122: 46048 | Q122: PMR
C123: 活塞环片密封 | D123: seal | E123: Z.P. ARROW | F123: 6.20.0.0001.3 | G123: 20 | H123: Ea | I123: M | J123: C | L123: MT9-B3 | M123: 2 | N123: 46048 | Q123: PMR
C124: 消音器 | D124: silencer | E124: FESTO 2316 | F124: U-1/4 | G124: 8 | H124: Ea | I124: M | J124: C | L124: MT7-A4 | M124: 1 | N124: 46048 | Q124: PMR
C125: 整流器 | D125: ballast | E125: Philips | F125: 44W-LED | G125: 1 | H125: Ea | I125: U | J125: C | L125: MT8-A3 | M125: 20 | N125: 46034 | Q125: Utility
C126: 桥架 | D126: wista | E126: bridge | F126: 002216-002-00-00 | G126: 1 | H126: Ea | I126: M | J126: C | L126: MT1-B6 | M126: 1 | N126: 46049 | Q126: PM1
C127: 加热灯管 | D127: strip lamp | E127: LAMBDA | F127: 090-100563-03 Emitter 3.95kw | G127: 40 | H127: Ea | I127: E | J127: A | L127: MT6-D3 | M127: 1 | N127: 46049 | Q127: EM2
C128: 搅拌缸轮子(黄) | D128: wheel | E128: SUPO | F128: Φ100*45 | G128: 4 | H128: Ea | I128: M | J128: C | L128: MT10-B6 | M128: 1 | N128: 46050 | Q128: PMR
C129: LED灯管 | D129: strip lamp | E129: SCON | F129: SC-T8-0912T SC-T8T 12W | G129: 12 | H129: Ea | I129: E | J129: A | L129: MT5-D1 | M129: 1 | N129: 46049 | Q129: EM1
...
